{
 "cells": [
  {
   "cell_type": "code",
   "execution_count": 1,
   "id": "c7c556d8",
   "metadata": {},
   "outputs": [],
   "source": [
    "import tensorflow as tf\n",
    "import scipy"
   ]
  },
  {
   "cell_type": "code",
   "execution_count": 2,
   "id": "dcb80f7e-a800-4675-87c6-92569a93f04d",
   "metadata": {},
   "outputs": [],
   "source": [
    "from keras.preprocessing.image import ImageDataGenerator\n",
    "from tensorflow.keras.models import Sequential\n",
    "from tensorflow.keras.layers import Dense"
   ]
  },
  {
   "cell_type": "code",
   "execution_count": 3,
   "id": "41063b8c-e1dc-4564-8843-ff82b4ca2a82",
   "metadata": {},
   "outputs": [],
   "source": [
    "#data preprocessing\n",
    "cnn = Sequential()\n",
    "\n",
    "train_datagen = ImageDataGenerator(\n",
    "    rescale = 1./255,\n",
    "    shear_range = 0.2,\n",
    "    zoom_range = 0.2,\n",
    "    horizontal_flip = True)"
   ]
  },
  {
   "cell_type": "code",
   "execution_count": 4,
   "id": "6cd791ba-ee8f-4752-b966-6df08520eb88",
   "metadata": {},
   "outputs": [
    {
     "name": "stdout",
     "output_type": "stream",
     "text": [
      "Found 18002 images belonging to 2 classes.\n"
     ]
    }
   ],
   "source": [
    "train_generator = train_datagen.flow_from_directory(\n",
    "    'dataset/training_set',\n",
    "    target_size=(64,64),\n",
    "    batch_size=32,\n",
    "    class_mode='binary')"
   ]
  },
  {
   "cell_type": "code",
   "execution_count": 5,
   "id": "6710fc8c-3ded-4e99-9b51-c8cb68bab503",
   "metadata": {},
   "outputs": [
    {
     "name": "stdout",
     "output_type": "stream",
     "text": [
      "Found 6998 images belonging to 2 classes.\n"
     ]
    }
   ],
   "source": [
    "test_datagen = ImageDataGenerator(rescale=1./255)\n",
    "validation_generator = test_datagen.flow_from_directory(\n",
    "    'dataset/test_set',\n",
    "    target_size=(64,64),\n",
    "    batch_size=32,\n",
    "    class_mode='binary')"
   ]
  },
  {
   "cell_type": "code",
   "execution_count": 6,
   "id": "d0910f37-cb23-4842-8c07-4e685c8ee33e",
   "metadata": {},
   "outputs": [],
   "source": [
    "#build cnn model\n",
    "#initialize\n",
    "cnn=tf.keras.models.Sequential()"
   ]
  },
  {
   "cell_type": "code",
   "execution_count": 7,
   "id": "c002bb2d-4b87-4d3b-bdce-f2b14ced94a4",
   "metadata": {},
   "outputs": [],
   "source": [
    "#convolution\n",
    "cnn.add(tf.keras.layers.Conv2D(filters=32,kernel_size=3,activation='relu',input_shape=[64,64,3]))"
   ]
  },
  {
   "cell_type": "code",
   "execution_count": 8,
   "id": "f08b83de-ba76-40a1-9630-321040750740",
   "metadata": {},
   "outputs": [],
   "source": [
    "#pooling\n",
    "cnn.add(tf.keras.layers.MaxPool2D(pool_size=2,strides=2))"
   ]
  },
  {
   "cell_type": "code",
   "execution_count": 9,
   "id": "d90b6932-4a25-4d2a-a7de-f0be76fe1521",
   "metadata": {},
   "outputs": [],
   "source": [
    "#add 1 more layer\n",
    "cnn.add(tf.keras.layers.Conv2D(filters=32,kernel_size=3,activation='relu'))\n",
    "cnn.add(tf.keras.layers.MaxPool2D(pool_size=2,strides=2))"
   ]
  },
  {
   "cell_type": "code",
   "execution_count": 10,
   "id": "23da88bb-17b8-4586-9270-b89c9699fbd9",
   "metadata": {},
   "outputs": [],
   "source": [
    "#flatten\n",
    "cnn.add(tf.keras.layers.Flatten())"
   ]
  },
  {
   "cell_type": "code",
   "execution_count": 11,
   "id": "bd42cbff-d143-45ae-acfa-58fdf8b933f5",
   "metadata": {},
   "outputs": [],
   "source": [
    "#full connection\n",
    "cnn.add(tf.keras.layers.Dense(units=128,activation='relu'))"
   ]
  },
  {
   "cell_type": "code",
   "execution_count": 30,
   "id": "99a3e228-d75b-4a9c-9383-615cde80055b",
   "metadata": {},
   "outputs": [],
   "source": [
    "#output layer\n",
    "cnn.add(tf.keras.layers.Dense(units=128,activation='sigmoid'))\n",
    "cnn.add(Dense(units=1, activation='sigmoid'))"
   ]
  },
  {
   "cell_type": "code",
   "execution_count": 31,
   "id": "769b186d-fe7a-44ea-99af-e748da0b21db",
   "metadata": {},
   "outputs": [],
   "source": [
    "#compile the model\n",
    "cnn.compile(optimizer='adam', loss='binary_crossentropy', metrics=['accuracy'])"
   ]
  },
  {
   "cell_type": "code",
   "execution_count": 34,
   "id": "413dea44-c69f-4a51-9ccb-33d04521ec8a",
   "metadata": {},
   "outputs": [
    {
     "name": "stdout",
     "output_type": "stream",
     "text": [
      "Epoch 1/5\n",
      "267/563 [=============>................] - ETA: 57s - loss: 0.6947 - accuracy: 0.4882"
     ]
    },
    {
     "ename": "UnknownError",
     "evalue": "Graph execution error:\n\nUnidentifiedImageError: cannot identify image file <_io.BytesIO object at 0x000001F4923B29F0>\nTraceback (most recent call last):\n\n  File \"D:\\annaconda\\envs\\env\\lib\\site-packages\\tensorflow\\python\\ops\\script_ops.py\", line 268, in __call__\n    ret = func(*args)\n\n  File \"D:\\annaconda\\envs\\env\\lib\\site-packages\\tensorflow\\python\\autograph\\impl\\api.py\", line 643, in wrapper\n    return func(*args, **kwargs)\n\n  File \"D:\\annaconda\\envs\\env\\lib\\site-packages\\tensorflow\\python\\data\\ops\\from_generator_op.py\", line 198, in generator_py_func\n    values = next(generator_state.get_iterator(iterator_id))\n\n  File \"D:\\annaconda\\envs\\env\\lib\\site-packages\\keras\\src\\engine\\data_adapter.py\", line 917, in wrapped_generator\n    for data in generator_fn():\n\n  File \"D:\\annaconda\\envs\\env\\lib\\site-packages\\keras\\src\\engine\\data_adapter.py\", line 1064, in generator_fn\n    yield x[i]\n\n  File \"D:\\annaconda\\envs\\env\\lib\\site-packages\\keras\\src\\preprocessing\\image.py\", line 116, in __getitem__\n    return self._get_batches_of_transformed_samples(index_array)\n\n  File \"D:\\annaconda\\envs\\env\\lib\\site-packages\\keras\\src\\preprocessing\\image.py\", line 370, in _get_batches_of_transformed_samples\n    img = image_utils.load_img(\n\n  File \"D:\\annaconda\\envs\\env\\lib\\site-packages\\keras\\src\\utils\\image_utils.py\", line 423, in load_img\n    img = pil_image.open(io.BytesIO(f.read()))\n\n  File \"D:\\annaconda\\envs\\env\\lib\\site-packages\\PIL\\Image.py\", line 3339, in open\n    raise UnidentifiedImageError(msg)\n\nPIL.UnidentifiedImageError: cannot identify image file <_io.BytesIO object at 0x000001F4923B29F0>\n\n\n\t [[{{node PyFunc}}]]\n\t [[IteratorGetNext]] [Op:__inference_train_function_13728]",
     "output_type": "error",
     "traceback": [
      "\u001b[1;31m---------------------------------------------------------------------------\u001b[0m",
      "\u001b[1;31mUnknownError\u001b[0m                              Traceback (most recent call last)",
      "Cell \u001b[1;32mIn[34], line 3\u001b[0m\n\u001b[0;32m      1\u001b[0m \u001b[38;5;66;03m#train the model\u001b[39;00m\n\u001b[1;32m----> 3\u001b[0m \u001b[43mcnn\u001b[49m\u001b[38;5;241;43m.\u001b[39;49m\u001b[43mfit\u001b[49m\u001b[43m(\u001b[49m\u001b[43mx\u001b[49m\u001b[38;5;241;43m=\u001b[39;49m\u001b[43mtrain_generator\u001b[49m\u001b[43m,\u001b[49m\u001b[43mvalidation_data\u001b[49m\u001b[38;5;241;43m=\u001b[39;49m\u001b[43mvalidation_generator\u001b[49m\u001b[43m,\u001b[49m\u001b[43mepochs\u001b[49m\u001b[38;5;241;43m=\u001b[39;49m\u001b[38;5;241;43m5\u001b[39;49m\u001b[43m)\u001b[49m\n",
      "File \u001b[1;32mD:\\annaconda\\envs\\env\\lib\\site-packages\\keras\\src\\utils\\traceback_utils.py:70\u001b[0m, in \u001b[0;36mfilter_traceback.<locals>.error_handler\u001b[1;34m(*args, **kwargs)\u001b[0m\n\u001b[0;32m     67\u001b[0m     filtered_tb \u001b[38;5;241m=\u001b[39m _process_traceback_frames(e\u001b[38;5;241m.\u001b[39m__traceback__)\n\u001b[0;32m     68\u001b[0m     \u001b[38;5;66;03m# To get the full stack trace, call:\u001b[39;00m\n\u001b[0;32m     69\u001b[0m     \u001b[38;5;66;03m# `tf.debugging.disable_traceback_filtering()`\u001b[39;00m\n\u001b[1;32m---> 70\u001b[0m     \u001b[38;5;28;01mraise\u001b[39;00m e\u001b[38;5;241m.\u001b[39mwith_traceback(filtered_tb) \u001b[38;5;28;01mfrom\u001b[39;00m \u001b[38;5;28;01mNone\u001b[39;00m\n\u001b[0;32m     71\u001b[0m \u001b[38;5;28;01mfinally\u001b[39;00m:\n\u001b[0;32m     72\u001b[0m     \u001b[38;5;28;01mdel\u001b[39;00m filtered_tb\n",
      "File \u001b[1;32mD:\\annaconda\\envs\\env\\lib\\site-packages\\tensorflow\\python\\eager\\execute.py:53\u001b[0m, in \u001b[0;36mquick_execute\u001b[1;34m(op_name, num_outputs, inputs, attrs, ctx, name)\u001b[0m\n\u001b[0;32m     51\u001b[0m \u001b[38;5;28;01mtry\u001b[39;00m:\n\u001b[0;32m     52\u001b[0m   ctx\u001b[38;5;241m.\u001b[39mensure_initialized()\n\u001b[1;32m---> 53\u001b[0m   tensors \u001b[38;5;241m=\u001b[39m pywrap_tfe\u001b[38;5;241m.\u001b[39mTFE_Py_Execute(ctx\u001b[38;5;241m.\u001b[39m_handle, device_name, op_name,\n\u001b[0;32m     54\u001b[0m                                       inputs, attrs, num_outputs)\n\u001b[0;32m     55\u001b[0m \u001b[38;5;28;01mexcept\u001b[39;00m core\u001b[38;5;241m.\u001b[39m_NotOkStatusException \u001b[38;5;28;01mas\u001b[39;00m e:\n\u001b[0;32m     56\u001b[0m   \u001b[38;5;28;01mif\u001b[39;00m name \u001b[38;5;129;01mis\u001b[39;00m \u001b[38;5;129;01mnot\u001b[39;00m \u001b[38;5;28;01mNone\u001b[39;00m:\n",
      "\u001b[1;31mUnknownError\u001b[0m: Graph execution error:\n\nUnidentifiedImageError: cannot identify image file <_io.BytesIO object at 0x000001F4923B29F0>\nTraceback (most recent call last):\n\n  File \"D:\\annaconda\\envs\\env\\lib\\site-packages\\tensorflow\\python\\ops\\script_ops.py\", line 268, in __call__\n    ret = func(*args)\n\n  File \"D:\\annaconda\\envs\\env\\lib\\site-packages\\tensorflow\\python\\autograph\\impl\\api.py\", line 643, in wrapper\n    return func(*args, **kwargs)\n\n  File \"D:\\annaconda\\envs\\env\\lib\\site-packages\\tensorflow\\python\\data\\ops\\from_generator_op.py\", line 198, in generator_py_func\n    values = next(generator_state.get_iterator(iterator_id))\n\n  File \"D:\\annaconda\\envs\\env\\lib\\site-packages\\keras\\src\\engine\\data_adapter.py\", line 917, in wrapped_generator\n    for data in generator_fn():\n\n  File \"D:\\annaconda\\envs\\env\\lib\\site-packages\\keras\\src\\engine\\data_adapter.py\", line 1064, in generator_fn\n    yield x[i]\n\n  File \"D:\\annaconda\\envs\\env\\lib\\site-packages\\keras\\src\\preprocessing\\image.py\", line 116, in __getitem__\n    return self._get_batches_of_transformed_samples(index_array)\n\n  File \"D:\\annaconda\\envs\\env\\lib\\site-packages\\keras\\src\\preprocessing\\image.py\", line 370, in _get_batches_of_transformed_samples\n    img = image_utils.load_img(\n\n  File \"D:\\annaconda\\envs\\env\\lib\\site-packages\\keras\\src\\utils\\image_utils.py\", line 423, in load_img\n    img = pil_image.open(io.BytesIO(f.read()))\n\n  File \"D:\\annaconda\\envs\\env\\lib\\site-packages\\PIL\\Image.py\", line 3339, in open\n    raise UnidentifiedImageError(msg)\n\nPIL.UnidentifiedImageError: cannot identify image file <_io.BytesIO object at 0x000001F4923B29F0>\n\n\n\t [[{{node PyFunc}}]]\n\t [[IteratorGetNext]] [Op:__inference_train_function_13728]"
     ]
    }
   ],
   "source": [
    "#train the model\n",
    "\n",
    "cnn.fit(x=train_generator,validation_data=validation_generator,epochs=5)"
   ]
  }
 ],
 "metadata": {
  "kernelspec": {
   "display_name": "Python 3 (ipykernel)",
   "language": "python",
   "name": "python3"
  },
  "language_info": {
   "codemirror_mode": {
    "name": "ipython",
    "version": 3
   },
   "file_extension": ".py",
   "mimetype": "text/x-python",
   "name": "python",
   "nbconvert_exporter": "python",
   "pygments_lexer": "ipython3",
   "version": "3.8.19"
  }
 },
 "nbformat": 4,
 "nbformat_minor": 5
}
